==========
Errors
==========

All ``pyzeebe`` exceptions inherit from :py:class:`PyZeebeError`

.. autoexception:: pyzeebe.errors.PyZeebeError

.. autoexception:: pyzeebe.errors.TaskNotFoundError

.. autoexception:: pyzeebe.errors.NoVariableNameGivenError

.. autoexception:: pyzeebe.errors.NoZeebeAdapterError

.. autoexception:: pyzeebe.errors.DuplicateTaskTypeError

.. autoexception:: pyzeebe.errors.ActivateJobsRequestInvalidError

.. autoexception:: pyzeebe.errors.JobAlreadyDeactivatedError

.. autoexception:: pyzeebe.errors.JobNotFoundError

.. autoexception:: pyzeebe.errors.MessageAlreadyExistsError

.. autoexception:: pyzeebe.exceptions.ProcessDefinitionNotFoundError

.. autoexception:: pyzeebe.exceptions.ProcessInstanceNotFoundError

.. autoexception:: pyzeebe.exceptions.ProcessHasNoStartEventError

.. autoexception:: pyzeebe.exceptions.ProcessInvalidError

.. autoexception:: pyzeebe.errors.InvalidJSONError

.. autoexception:: pyzeebe.errors.ZeebeBackPressureError

.. autoexception:: pyzeebe.errors.ZeebeGatewayUnavailableError

.. autoexception:: pyzeebe.errors.ZeebeInternalError

.. autoexception:: pyzeebe.errors.InvalidOAuthCredentialsError

.. autoexception:: pyzeebe.errors.InvalidCamundaCloudCredentialsError
