==========
Exceptions
==========

All ``pyzeebe`` exceptions inherit from :py:class:`PyZeebeError`

.. autoexception:: pyzeebe.exceptions.PyZeebeError

.. autoexception:: pyzeebe.exceptions.TaskNotFoundError

.. autoexception:: pyzeebe.exceptions.NoVariableNameGivenError

.. autoexception:: pyzeebe.exceptions.NoZeebeAdapterError

.. autoexception:: pyzeebe.exceptions.DuplicateTaskTypeError

.. autoexception:: pyzeebe.exceptions.ActivateJobsRequestInvalidError

.. autoexception:: pyzeebe.exceptions.JobAlreadyDeactivatedError

.. autoexception:: pyzeebe.exceptions.JobNotFoundError

.. autoexception:: pyzeebe.exceptions.MessageAlreadyExistsError

.. autoexception:: pyzeebe.exceptions.WorkflowNotFoundError

.. autoexception:: pyzeebe.exceptions.WorkflowInstanceNotFoundError

.. autoexception:: pyzeebe.exceptions.WorkflowHasNoStartEventError

.. autoexception:: pyzeebe.exceptions.WorkflowInvalidError

.. autoexception:: pyzeebe.exceptions.InvalidJSONError

.. autoexception:: pyzeebe.exceptions.ZeebeBackPressureError

.. autoexception:: pyzeebe.exceptions.ZeebeGatewayUnavailableError

.. autoexception:: pyzeebe.exceptions.ZeebeInternalError

.. autoexception:: pyzeebe.exceptions.InvalidOAuthCredentialsError

.. autoexception:: pyzeebe.exceptions.InvalidCamundaCloudCredentialsError
